The error was produced on SageMaker instance's notebook with either conda_tensorflow_p36 or conda_tensorflow_p27 kernels
